Workbook

Sheet Model_1_test18
A1: Match | B1: T1_ANA | C1: T2_ANA | D1: FW_mean_goal_diff | E1: GK_Cap_Difference | F1: MF_Avg_cap_diff | G1: Round_category | H1: Coach Salary Difference (EURO) | I1: Ranking Difference (April 2026) | J1: xG difference | K1: FW_avg_Cap_Difference | L1: DF_Avg_cap_diff | M1: Squad Goal Rate Difference | N1: MedianAge diff | O1: Y_Goal_difference
A2: Mexico vs South Africa | B2: MEX | C2: RSA | D2: =ABS(SUM(_xlfn.XLOOKUP(B2,Final_48_team_stats!B:B,Final_48_team_stats!M:M)-_xlfn.XLOOKUP(C2,Final_48_team_stats!B:B,Final_48_team_stats!M:M))) -> 5.125 | E2: =ABS(SUM(_xlfn.XLOOKUP(B2,Final_48_team_stats!B:B,Final_48_team_stats!J:J)-_xlfn.XLOOKUP(Model_1_test18!C2,Final_48_team_stats!B:B,Final_48_team_stats!J:J))) -> 34 | F2: =ABS(SUM(_xlfn.XLOOKUP(B2,Final_48_team_stats!B:B,Final_48_team_stats!K:K)-_xlfn.XLOOKUP(C2,Final_48_team_stats!B:B,Final_48_team_stats!K:K))) -> 0.15 | G2: 1 | H2: 1600000 | I2: 45 | J2: 1.39 | K2: =ABS(SUM(_xlfn.XLOOKUP(B2,Final_48_team_stats!B:B,Final_48_team_stats!I:I)-(_xlfn.XLOOKUP(C2,Final_48_team_stats!B:B,Final_48_team_stats!I:I)))) -> 28.5 | L2: =ABS(SUM(_xlfn.XLOOKUP(B2,Final_48_team_stats!B:B,Final_48_team_stats!H:H)-(_xlfn.XLOOKUP(C2,Final_48_team_stats!B:B,Final_48_team_stats!H:H)))) -> 49.142857 | M2: =ABS(SUM(_xlfn.XLOOKUP(B2,Final_48_team_stats!B:B,Final_48_team_stats!Q:Q)-(_xlfn.XLOOKUP(C2,Final_48_team_stats!B:B,Final_48_team_stats!Q:Q)))) -> 0.031836811 | N2: =ABS(SUM(_xlfn.XLOOKUP(B2,Final_48_team_stats!B:B,Final_48_team_stats!G:G)-(_xlfn.XLOOKUP(C2,Final_48_team_stats!B:B,Final_48_team_stats!G:G)))) -> 2.5 | O2: 2
A3: South Korea vs Czech Republic | B3: KOR | C3: CZE | D3: =ABS(SUM(_xlfn.XLOOKUP(B3,Final_48_team_stats!B:B,Final_48_team_stats!M:M)-_xlfn.XLOOKUP(C3,Final_48_team_stats!B:B,Final_48_team_stats!M:M))) -> 17.095238 | E3: =ABS(SUM(_xlfn.XLOOKUP(B3,Final_48_team_stats!B:B,Final_48_team_stats!J:J)-_xlfn.XLOOKUP(Model_1_test18!C3,Final_48_team_stats!B:B,Final_48_team_stats!J:J))) -> 34.333333 | F3: =ABS(SUM(_xlfn.XLOOKUP(B3,Final_48_team_stats!B:B,Final_48_team_stats!K:K)-_xlfn.XLOOKUP(C3,Final_48_team_stats!B:B,Final_48_team_stats!K:K))) -> 0.61038961 | G3: 1 | H3: 1980000 | I3: 16 | J3: 1.47 | K3: =ABS(SUM(_xlfn.XLOOKUP(B3,Final_48_team_stats!B:B,Final_48_team_stats!I:I)-(_xlfn.XLOOKUP(C3,Final_48_team_stats!B:B,Final_48_team_stats!I:I)))) -> 43.952381 | L3: =ABS(SUM(_xlfn.XLOOKUP(B3,Final_48_team_stats!B:B,Final_48_team_stats!H:H)-(_xlfn.XLOOKUP(C3,Final_48_team_stats!B:B,Final_48_team_stats!H:H)))) -> 3.5555556 | M3: =ABS(SUM(_xlfn.XLOOKUP(B3,Final_48_team_stats!B:B,Final_48_team_stats!Q:Q)-(_xlfn.XLOOKUP(C3,Final_48_team_stats!B:B,Final_48_team_stats!Q:Q)))) -> 0.013722976 | N3: =ABS(SUM(_xlfn.XLOOKUP(B3,Final_48_team_stats!B:B,Final_48_team_stats!G:G)-(_xlfn.XLOOKUP(C3,Final_48_team_stats!B:B,Final_48_team_stats!G:G)))) -> 1 | O3: 1
A4: Canada vs Bosnia & Herzegovina | B4: CAN | C4: BIH | D4: =ABS(SUM(_xlfn.XLOOKUP(B4,Final_48_team_stats!B:B,Final_48_team_stats!M:M)-_xlfn.XLOOKUP(C4,Final_48_team_stats!B:B,Final_48_team_stats!M:M))) -> 0.28571429 | E4: =ABS(SUM(_xlfn.XLOOKUP(B4,Final_48_team_stats!B:B,Final_48_team_stats!J:J)-_xlfn.XLOOKUP(Model_1_test18!C4,Final_48_team_stats!B:B,Final_48_team_stats!J:J))) -> 7.6666667 | F4: =ABS(SUM(_xlfn.XLOOKUP(B4,Final_48_team_stats!B:B,Final_48_team_stats!K:K)-_xlfn.XLOOKUP(C4,Final_48_team_stats!B:B,Final_48_team_stats!K:K))) -> 23.910714 | G4: 1 | H4: 2270000 | I4: 35 | J4: 0.27 | K4: =ABS(SUM(_xlfn.XLOOKUP(B4,Final_48_team_stats!B:B,Final_48_team_stats!I:I)-(_xlfn.XLOOKUP(C4,Final_48_team_stats!B:B,Final_48_team_stats!I:I)))) -> 8.4285714 | L4: =ABS(SUM(_xlfn.XLOOKUP(B4,Final_48_team_stats!B:B,Final_48_team_stats!H:H)-(_xlfn.XLOOKUP(C4,Final_48_team_stats!B:B,Final_48_team_stats!H:H)))) -> 11.375 | M4: =ABS(SUM(_xlfn.XLOOKUP(B4,Final_48_team_stats!B:B,Final_48_team_stats!Q:Q)-(_xlfn.XLOOKUP(C4,Final_48_team_stats!B:B,Final_48_team_stats!Q:Q)))) -> 0.016219608 | N4: =ABS(SUM(_xlfn.XLOOKUP(B4,Final_48_team_stats!B:B,Final_48_team_stats!G:G)-(_xlfn.XLOOKUP(C4,Final_48_team_stats!B:B,Final_48_team_stats!G:G)))) -> 1 | O4: 0
A5: USA vs Paraguay | B5: USA | C5: PAR | D5: =ABS(SUM(_xlfn.XLOOKUP(B5,Final_48_team_stats!B:B,Final_48_team_stats!M:M)-_xlfn.XLOOKUP(C5,Final_48_team_stats!B:B,Final_48_team_stats!M:M))) -> 8.0952381 | E5: =ABS(SUM(_xlfn.XLOOKUP(B5,Final_48_team_stats!B:B,Final_48_team_stats!J:J)-_xlfn.XLOOKUP(Model_1_test18!C5,Final_48_team_stats!B:B,Final_48_team_stats!J:J))) -> 10.666667 | F5: =ABS(SUM(_xlfn.XLOOKUP(B5,Final_48_team_stats!B:B,Final_48_team_stats!K:K)-_xlfn.XLOOKUP(C5,Final_48_team_stats!B:B,Final_48_team_stats!K:K))) -> 17.111111 | G5: 1 | H5: 2700000 | I5: 24 | J5: 0.88 | K5: =ABS(SUM(_xlfn.XLOOKUP(B5,Final_48_team_stats!B:B,Final_48_team_stats!I:I)-(_xlfn.XLOOKUP(C5,Final_48_team_stats!B:B,Final_48_team_stats!I:I)))) -> 15.857143 | L5: =ABS(SUM(_xlfn.XLOOKUP(B5,Final_48_team_stats!B:B,Final_48_team_stats!H:H)-(_xlfn.XLOOKUP(C5,Final_48_team_stats!B:B,Final_48_team_stats!H:H)))) -> 0.35 | M5: =ABS(SUM(_xlfn.XLOOKUP(B5,Final_48_team_stats!B:B,Final_48_team_stats!Q:Q)-(_xlfn.XLOOKUP(C5,Final_48_team_stats!B:B,Final_48_team_stats!Q:Q)))) -> 0.053126036 | N5: =ABS(SUM(_xlfn.XLOOKUP(B5,Final_48_team_stats!B:B,Final_48_team_stats!G:G)-(_xlfn.XLOOKUP(C5,Final_48_team_stats!B:B,Final_48_team_stats!G:G)))) -> 2.5 | O5: 3
A6: Qatar vs Switzerland | B6: QAT | C6: SUI | D6: =ABS(SUM(_xlfn.XLOOKUP(B6,Final_48_team_stats!B:B,Final_48_team_stats!M:M)-_xlfn.XLOOKUP(C6,Final_48_team_stats!B:B,Final_48_team_stats!M:M))) -> 8.6825397 | E6: =ABS(SUM(_xlfn.XLOOKUP(B6,Final_48_team_stats!B:B,Final_48_team_stats!J:J)-_xlfn.XLOOKUP(Model_1_test18!C6,Final_48_team_stats!B:B,Final_48_team_stats!J:J))) -> 10.333333 | F6: =ABS(SUM(_xlfn.XLOOKUP(B6,Final_48_team_stats!B:B,Final_48_team_stats!K:K)-_xlfn.XLOOKUP(C6,Final_48_team_stats!B:B,Final_48_team_stats!K:K))) -> 14.925 | G6: 1 | H6: 800000 | I6: 36 | J6: 2.6 | K6: =ABS(SUM(_xlfn.XLOOKUP(B6,Final_48_team_stats!B:B,Final_48_team_stats!I:I)-(_xlfn.XLOOKUP(C6,Final_48_team_stats!B:B,Final_48_team_stats!I:I)))) -> 31.31746 | L6: =ABS(SUM(_xlfn.XLOOKUP(B6,Final_48_team_stats!B:B,Final_48_team_stats!H:H)-(_xlfn.XLOOKUP(C6,Final_48_team_stats!B:B,Final_48_team_stats!H:H)))) -> 6.1666667 | M6: =ABS(SUM(_xlfn.XLOOKUP(B6,Final_48_team_stats!B:B,Final_48_team_stats!Q:Q)-(_xlfn.XLOOKUP(C6,Final_48_team_stats!B:B,Final_48_team_stats!Q:Q)))) -> 0.036424276 | N6: =ABS(SUM(_xlfn.XLOOKUP(B6,Final_48_team_stats!B:B,Final_48_team_stats!G:G)-(_xlfn.XLOOKUP(C6,Final_48_team_stats!B:B,Final_48_team_stats!G:G)))) -> 0.5 | O6: 0
A7: Brazil vs Morocco | B7: BRA | C7: MAR | D7: =ABS(SUM(_xlfn.XLOOKUP(B7,Final_48_team_stats!B:B,Final_48_team_stats!M:M)-_xlfn.XLOOKUP(C7,Final_48_team_stats!B:B,Final_48_team_stats!M:M))) -> 0.35555556 | E7: =ABS(SUM(_xlfn.XLOOKUP(B7,Final_48_team_stats!B:B,Final_48_team_stats!J:J)-_xlfn.XLOOKUP(Model_1_test18!C7,Final_48_team_stats!B:B,Final_48_team_stats!J:J))) -> 8 | F7: =ABS(SUM(_xlfn.XLOOKUP(B7,Final_48_team_stats!B:B,Final_48_team_stats!K:K)-_xlfn.XLOOKUP(C7,Final_48_team_stats!B:B,Final_48_team_stats!K:K))) -> 13.888889 | G7: 1 | H7: 8725000 | I7: 2 | J7: 0.11 | K7: =ABS(SUM(_xlfn.XLOOKUP(B7,Final_48_team_stats!B:B,Final_48_team_stats!I:I)-(_xlfn.XLOOKUP(C7,Final_48_team_stats!B:B,Final_48_team_stats!I:I)))) -> 5.7333333 | L7: =ABS(SUM(_xlfn.XLOOKUP(B7,Final_48_team_stats!B:B,Final_48_team_stats!H:H)-(_xlfn.XLOOKUP(C7,Final_48_team_stats!B:B,Final_48_team_stats!H:H)))) -> 11.541667 | M7: =ABS(SUM(_xlfn.XLOOKUP(B7,Final_48_team_stats!B:B,Final_48_team_stats!Q:Q)-(_xlfn.XLOOKUP(C7,Final_48_team_stats!B:B,Final_48_team_stats!Q:Q)))) -> 0.025537718 | N7: =ABS(SUM(_xlfn.XLOOKUP(B7,Final_48_team_stats!B:B,Final_48_team_stats!G:G)-(_xlfn.XLOOKUP(C7,Final_48_team_stats!B:B,Final_48_team_stats!G:G)))) -> 3 | O7: 0
A8: Haiti vs Scotland | B8: HAI | C8: SCO | D8: =ABS(SUM(_xlfn.XLOOKUP(B8,Final_48_team_stats!B:B,Final_48_team_stats!M:M)-_xlfn.XLOOKUP(C8,Final_48_team_stats!B:B,Final_48_team_stats!M:M))) -> 6.6190476 | E8: =ABS(SUM(_xlfn.XLOOKUP(B8,Final_48_team_stats!B:B,Final_48_team_stats!J:J)-_xlfn.XLOOKUP(Model_1_test18!C8,Final_48_team_stats!B:B,Final_48_team_stats!J:J))) -> 1.3333333 | F8: =ABS(SUM(_xlfn.XLOOKUP(B8,Final_48_team_stats!B:B,Final_48_team_stats!K:K)-_xlfn.XLOOKUP(C8,Final_48_team_stats!B:B,Final_48_team_stats!K:K))) -> 37.333333 | G8: 1 | H8: 310000 | I8: 40 | J8: 0 | K8: =ABS(SUM(_xlfn.XLOOKUP(B8,Final_48_team_stats!B:B,Final_48_team_stats!I:I)-(_xlfn.XLOOKUP(C8,Final_48_team_stats!B:B,Final_48_team_stats!I:I)))) -> 6.4126984 | L8: =ABS(SUM(_xlfn.XLOOKUP(B8,Final_48_team_stats!B:B,Final_48_team_stats!H:H)-(_xlfn.XLOOKUP(C8,Final_48_team_stats!B:B,Final_48_team_stats!H:H)))) -> 18.466667 | M8: =ABS(SUM(_xlfn.XLOOKUP(B8,Final_48_team_stats!B:B,Final_48_team_stats!Q:Q)-(_xlfn.XLOOKUP(C8,Final_48_team_stats!B:B,Final_48_team_stats!Q:Q)))) -> 0.083575447 | N8: =ABS(SUM(_xlfn.XLOOKUP(B8,Final_48_team_stats!B:B,Final_48_team_stats!G:G)-(_xlfn.XLOOKUP(C8,Final_48_team_stats!B:B,Final_48_team_stats!G:G)))) -> 3 | O8: 1
A9: Australia vs Turkey | B9: AUS | C9: TUR | D9: =ABS(SUM(_xlfn.XLOOKUP(B9,Final_48_team_stats!B:B,Final_48_team_stats!M:M)-_xlfn.XLOOKUP(C9,Final_48_team_stats!B:B,Final_48_team_stats!M:M))) -> 9.2222222 | E9: =ABS(SUM(_xlfn.XLOOKUP(B9,Final_48_team_stats!B:B,Final_48_team_stats!J:J)-_xlfn.XLOOKUP(Model_1_test18!C9,Final_48_team_stats!B:B,Final_48_team_stats!J:J))) -> 9 | F9: =ABS(SUM(_xlfn.XLOOKUP(B9,Final_48_team_stats!B:B,Final_48_team_stats!K:K)-_xlfn.XLOOKUP(C9,Final_48_team_stats!B:B,Final_48_team_stats!K:K))) -> 23 | G9: 1 | H9: 1595000 | I9: 5 | J9: 0.18 | K9: =ABS(SUM(_xlfn.XLOOKUP(B9,Final_48_team_stats!B:B,Final_48_team_stats!I:I)-(_xlfn.XLOOKUP(C9,Final_48_team_stats!B:B,Final_48_team_stats!I:I)))) -> 32.638889 | L9: =ABS(SUM(_xlfn.XLOOKUP(B9,Final_48_team_stats!B:B,Final_48_team_stats!H:H)-(_xlfn.XLOOKUP(C9,Final_48_team_stats!B:B,Final_48_team_stats!H:H)))) -> 9.9666667 | M9: =ABS(SUM(_xlfn.XLOOKUP(B9,Final_48_team_stats!B:B,Final_48_team_stats!Q:Q)-(_xlfn.XLOOKUP(C9,Final_48_team_stats!B:B,Final_48_team_stats!Q:Q)))) -> 0.048554337 | N9: =ABS(SUM(_xlfn.XLOOKUP(B9,Final_48_team_stats!B:B,Final_48_team_stats!G:G)-(_xlfn.XLOOKUP(C9,Final_48_team_stats!B:B,Final_48_team_stats!G:G)))) -> 0.5 | O9: 2
A10: Germany vs Curacao | B10: GER | C10: CUW | D10: =ABS(SUM(_xlfn.XLOOKUP(B10,Final_48_team_stats!B:B,Final_48_team_stats!M:M)-_xlfn.XLOOKUP(C10,Final_48_team_stats!B:B,Final_48_team_stats!M:M))) -> 4.375 | E10: =ABS(SUM(_xlfn.XLOOKUP(B10,Final_48_team_stats!B:B,Final_48_team_stats!J:J)-_xlfn.XLOOKUP(Model_1_test18!C10,Final_48_team_stats!B:B,Final_48_team_stats!J:J))) -> 19 | F10: =ABS(SUM(_xlfn.XLOOKUP(B10,Final_48_team_stats!B:B,Final_48_team_stats!K:K)-_xlfn.XLOOKUP(C10,Final_48_team_stats!B:B,Final_48_team_stats!K:K))) -> 2.5454545 | G10: 1 | H10: 4704000 | I10: 72 | J10: 3.81 | K10: =ABS(SUM(_xlfn.XLOOKUP(B10,Final_48_team_stats!B:B,Final_48_team_stats!I:I)-(_xlfn.XLOOKUP(C10,Final_48_team_stats!B:B,Final_48_team_stats!I:I)))) -> 0.375 | L10: =ABS(SUM(_xlfn.XLOOKUP(B10,Final_48_team_stats!B:B,Final_48_team_stats!H:H)-(_xlfn.XLOOKUP(C10,Final_48_team_stats!B:B,Final_48_team_stats!H:H)))) -> 21.375 | M10: =ABS(SUM(_xlfn.XLOOKUP(B10,Final_48_team_stats!B:B,Final_48_team_stats!Q:Q)-(_xlfn.XLOOKUP(C10,Final_48_team_stats!B:B,Final_48_team_stats!Q:Q)))) -> 0.0062846056 | N10: =ABS(SUM(_xlfn.XLOOKUP(B10,Final_48_team_stats!B:B,Final_48_team_stats!G:G)-(_xlfn.XLOOKUP(C10,Final_48_team_stats!B:B,Final_48_team_stats!G:G)))) -> 1 | O10: 6
A11: Netherlands vs Japan | B11: NED | C11: JPN | D11: =ABS(SUM(_xlfn.XLOOKUP(B11,Final_48_team_stats!B:B,Final_48_team_stats!M:M)-_xlfn.XLOOKUP(C11,Final_48_team_stats!B:B,Final_48_team_stats!M:M))) -> 8.8857143 | E11: =ABS(SUM(_xlfn.XLOOKUP(B11,Final_48_team_stats!B:B,Final_48_team_stats!J:J)-_xlfn.XLOOKUP(Model_1_test18!C11,Final_48_team_stats!B:B,Final_48_team_stats!J:J))) -> 1 | F11: =ABS(SUM(_xlfn.XLOOKUP(B11,Final_48_team_stats!B:B,Final_48_team_stats!K:K)-_xlfn.XLOOKUP(C11,Final_48_team_stats!B:B,Final_48_team_stats!K:K))) -> 9.6388889 | G11: 1 | H11: 2135000 | I11: 11 | J11: 0.19 | K11: =ABS(SUM(_xlfn.XLOOKUP(B11,Final_48_team_stats!B:B,Final_48_team_stats!I:I)-(_xlfn.XLOOKUP(C11,Final_48_team_stats!B:B,Final_48_team_stats!I:I)))) -> 27.057143 | L11: =ABS(SUM(_xlfn.XLOOKUP(B11,Final_48_team_stats!B:B,Final_48_team_stats!H:H)-(_xlfn.XLOOKUP(C11,Final_48_team_stats!B:B,Final_48_team_stats!H:H)))) -> 0.5 | M11: =ABS(SUM(_xlfn.XLOOKUP(B11,Final_48_team_stats!B:B,Final_48_team_stats!Q:Q)-(_xlfn.XLOOKUP(C11,Final_48_team_stats!B:B,Final_48_team_stats!Q:Q)))) -> 0.039509394 | N11: =ABS(SUM(_xlfn.XLOOKUP(B11,Final_48_team_stats!B:B,Final_48_team_stats!G:G)-(_xlfn.XLOOKUP(C11,Final_48_team_stats!B:B,Final_48_team_stats!G:G)))) -> 0 | O11: 0
A12: Saudi Arabia vs Uruguay | B12: KSA | C12: URU | D12: =ABS(SUM(_xlfn.XLOOKUP(B12,Final_48_team_stats!B:B,Final_48_team_stats!M:M)-_xlfn.XLOOKUP(C12,Final_48_team_stats!B:B,Final_48_team_stats!M:M))) -> 5.9142857 | E12: =ABS(SUM(_xlfn.XLOOKUP(B12,Final_48_team_stats!B:B,Final_48_team_stats!J:J)-_xlfn.XLOOKUP(Model_1_test18!C12,Final_48_team_stats!B:B,Final_48_team_stats!J:J))) -> 26.333333 | F12: =ABS(SUM(_xlfn.XLOOKUP(B12,Final_48_team_stats!B:B,Final_48_team_stats!K:K)-_xlfn.XLOOKUP(C12,Final_48_team_stats!B:B,Final_48_team_stats!K:K))) -> 3.7575758 | G12: 1 | H12: 1960000 | I12: 44 | J12: 0.51 | K12: =ABS(SUM(_xlfn.XLOOKUP(B12,Final_48_team_stats!B:B,Final_48_team_stats!I:I)-(_xlfn.XLOOKUP(C12,Final_48_team_stats!B:B,Final_48_team_stats!I:I)))) -> 21.714286 | L12: =ABS(SUM(_xlfn.XLOOKUP(B12,Final_48_team_stats!B:B,Final_48_team_stats!H:H)-(_xlfn.XLOOKUP(C12,Final_48_team_stats!B:B,Final_48_team_stats!H:H)))) -> 10.214286 | M12: =ABS(SUM(_xlfn.XLOOKUP(B12,Final_48_team_stats!B:B,Final_48_team_stats!Q:Q)-(_xlfn.XLOOKUP(C12,Final_48_team_stats!B:B,Final_48_team_stats!Q:Q)))) -> 0.02424583 | N12: =ABS(SUM(_xlfn.XLOOKUP(B12,Final_48_team_stats!B:B,Final_48_team_stats!G:G)-(_xlfn.XLOOKUP(C12,Final_48_team_stats!B:B,Final_48_team_stats!G:G)))) -> 0.5 | O12: 0
A13: Belgium vs Egypt | B13: BEL | C13: EGY | D13: =ABS(SUM(_xlfn.XLOOKUP(B13,Final_48_team_stats!B:B,Final_48_team_stats!M:M)-_xlfn.XLOOKUP(C13,Final_48_team_stats!B:B,Final_48_team_stats!M:M))) -> 4.5952381 | E13: =ABS(SUM(_xlfn.XLOOKUP(B13,Final_48_team_stats!B:B,Final_48_team_stats!J:J)-_xlfn.XLOOKUP(Model_1_test18!C13,Final_48_team_stats!B:B,Final_48_team_stats!J:J))) -> 15.75 | F13: =ABS(SUM(_xlfn.XLOOKUP(B13,Final_48_team_stats!B:B,Final_48_team_stats!K:K)-_xlfn.XLOOKUP(C13,Final_48_team_stats!B:B,Final_48_team_stats!K:K))) -> 30.196429 | G13: 1 | H13: 1544000 | I13: 20 | J13: 1.05 | K13: =ABS(SUM(_xlfn.XLOOKUP(B13,Final_48_team_stats!B:B,Final_48_team_stats!I:I)-(_xlfn.XLOOKUP(C13,Final_48_team_stats!B:B,Final_48_team_stats!I:I)))) -> 3.7142857 | L13: =ABS(SUM(_xlfn.XLOOKUP(B13,Final_48_team_stats!B:B,Final_48_team_stats!H:H)-(_xlfn.XLOOKUP(C13,Final_48_team_stats!B:B,Final_48_team_stats!H:H)))) -> 2.0694444 | M13: =ABS(SUM(_xlfn.XLOOKUP(B13,Final_48_team_stats!B:B,Final_48_team_stats!Q:Q)-(_xlfn.XLOOKUP(C13,Final_48_team_stats!B:B,Final_48_team_stats!Q:Q)))) -> 0.043763647 | N13: =ABS(SUM(_xlfn.XLOOKUP(B13,Final_48_team_stats!B:B,Final_48_team_stats!G:G)-(_xlfn.XLOOKUP(C13,Final_48_team_stats!B:B,Final_48_team_stats!G:G)))) -> 3 | O13: 0
... A105: Spain vs Argentina | B105: ESP | C105: ARG | D105: =ABS(SUM(_xlfn.XLOOKUP(B105,Final_48_team_stats!B:B,Final_48_team_stats!M:M)-_xlfn.XLOOKUP(C105,Final_48_team_stats!B:B,Final_48_team_stats!M:M))) -> 15.392857 | E105: =ABS(SUM(_xlfn.XLOOKUP(B105,Final_48_team_stats!B:B,Final_48_team_stats!J:J)-_xlfn.XLOOKUP(Model_1_test18!C105,Final_48_team_stats!B:B,Final_48_team_stats!J:J))) -> 0.66666667 | F105: =ABS(SUM(_xlfn.XLOOKUP(B105,Final_48_team_stats!B:B,Final_48_team_stats!K:K)-_xlfn.XLOOKUP(C105,Final_48_team_stats!B:B,Final_48_team_stats!K:K))) -> 14.464286 | G105: 8 | H105: 1000000 | I105: 1 | J105: 2.07 | K105: =ABS(SUM(_xlfn.XLOOKUP(B105,Final_48_team_stats!B:B,Final_48_team_stats!I:I)-(_xlfn.XLOOKUP(C105,Final_48_team_stats!B:B,Final_48_team_stats!I:I)))) -> 21.857143 | L105: =ABS(SUM(_xlfn.XLOOKUP(B105,Final_48_team_stats!B:B,Final_48_team_stats!H:H)-(_xlfn.XLOOKUP(C105,Final_48_team_stats!B:B,Final_48_team_stats!H:H)))) -> 29.375 | M105: =ABS(SUM(_xlfn.XLOOKUP(B105,Final_48_team_stats!B:B,Final_48_team_stats!Q:Q)-(_xlfn.XLOOKUP(C105,Final_48_team_stats!B:B,Final_48_team_stats!Q:Q)))) -> 0.020787677 | N105: =ABS(SUM(_xlfn.XLOOKUP(B105,Final_48_team_stats!B:B,Final_48_team_stats!G:G)-(_xlfn.XLOOKUP(C105,Final_48_team_stats!B:B,Final_48_team_stats!G:G)))) -> 1.5 | O105: 1

Sheet Final_48_team_stats
B1: m | C1: CAPS_total | D1: GOALS_total | E1: CAPS_average | F1: GOALS_average | G1: Age_median | H1: CAPS_DF_mean | I1: CAPS_FW_mean | J1: CAPS_GK_mean | K1: CAPS_MF_mean | L1: GOALS_DF_mean | M1: GOALS_FW_mean | N1: GOALS_GK_mean | O1: GOALS_MF_mean | Q1: Squag goal rate- Goal/cap
A2: 0 | B2: ALG | C2: 778 | D2: 122 | E2: 29.923077 | F2: 4.6923077 | G2: 26 | H2: 36 | I2: 31.142857 | J2: 4.6666667 | K2: 31.714286 | L2: 2.7777778 | M2: 11 | N2: 0 | O2: 2.8571429 | Q2: =D2/C2 -> 0.15681234
A3: 1 | B3: ARG | C3: 1251 | D3: 223 | E3: 48.115385 | F3: 8.5769231 | G3: 28 | H3: 49.5 | I3: 52.857143 | J3: 23.666667 | K3: 51.75 | L3: 2 | M3: 25.142857 | N3: 0 | O3: 3.875 | Q3: =D3/C3 -> 0.17825739
A4: 2 | B4: AUS | C4: 1003 | D4: 149 | E4: 38.576923 | F4: 5.7307692 | G4: 26.5 | H4: 29.7 | I4: 58.75 | J4: 20.333333 | K4: 35 | L4: 1.5 | M4: 14 | N4: 1 | O4: 3.8 | Q4: =D4/C4 -> 0.14855434
A5: 3 | B5: AUT | C5: 1068 | D5: 154 | E5: 41.076923 | F5: 5.9230769 | G5: 28 | H5: 37.625 | I5: 68 | J5: 16.333333 | K5: 40.545455 | L5: 2.875 | M5: 19.75 | N5: 0 | O5: 4.7272727 | Q5: =D5/C5 -> 0.14419476
A6: 4 | B6: BEL | C6: 1085 | D6: 214 | E6: 41.730769 | F6: 8.2307692 | G6: 25.5 | H6: 27.444444 | I6: 47 | J6: 37 | K6: 55.625 | L6: 2.1111111 | M6: 20.166667 | N6: 0 | O6: 9.25 | Q6: =D6/C6 -> 0.19723502
A7: 5 | B7: BIH | C7: 597 | D7: 93 | E7: 22.961538 | F7: 3.5769231 | G7: 27 | H7: 22.625 | I7: 34.285714 | J7: 9.6666667 | K7: 18.375 | L7: 0.625 | M7: 12 | N7: 0 | O7: 0.5 | Q7: =D7/C7 -> 0.15577889
A8: 6 | B8: BRA | C8: 916 | D8: 152 | E8: 35.230769 | F8: 5.8461538 | G8: 28.5 | H8: 32.875 | I8: 33.333333 | J8: 40.333333 | K8: 38.666667 | L8: 1.5 | M8: 12.555556 | N8: 0 | O8: 4.5 | Q8: =D8/C8 -> 0.16593886
A9: 7 | B9: CAN | C9: 953 | D9: 133 | E9: 36.653846 | F9: 5.1153846 | G9: 26 | H9: 34 | I9: 42.714286 | J9: 17.333333 | K9: 42.285714 | L9: 2.2222222 | M9: 12.285714 | N9: 0 | O9: 3.8571429 | Q9: =D9/C9 -> 0.13955929
A10: 8 | B10: CIV | C10: 703 | D10: 83 | E10: 27.038462 | F10: 3.1923077 | G10: 25 | H10: 27.375 | I10: 19.333333 | J10: 13 | K10: 45.166667 | L10: 0.875 | M10: 4.2222222 | N10: 0 | O10: 6.3333333 | Q10: =D10/C10 -> 0.11806543
A11: 9 | B11: COD | C11: 796 | D11: 82 | E11: 30.615385 | F11: 3.1538462 | G11: 29 | H11: 31.5 | I11: 38.285714 | J11: 11 | K11: 30.375 | L11: 1.75 | M11: 7.8571429 | N11: 0 | O11: 1.625 | Q11: =D11/C11 -> 0.10301508
A12: 10 | B12: COL | C12: 1042 | D12: 108 | E12: 40.076923 | F12: 4.1538462 | G12: 29 | H12: 39.444444 | I12: 22.333333 | J12: 61.333333 | K12: 46.125 | L12: 2 | M12: 6.3333333 | N12: 0 | O12: 6.5 | Q12: =D12/C12 -> 0.10364683
A13: 11 | B13: CPV | C13: 823 | D13: 75 | E13: 31.653846 | F13: 2.8846154 | G13: 29 | H13: 27.125 | I13: 46.333333 | J13: 34 | K13: 30.416667 | L13: 1.25 | M13: 11.666667 | N13: 0 | O13: 2.5 | Q13: =D13/C13 -> 0.091130012
... A49: 47 | B49: UZB | C49: 834 | D49: 116 | E49: 32.076923 | F49: 4.4615385 | G49: 28 | H49: 24.5 | I49: 62.333333 | J49: 16.666667 | K49: 35.2 | L49: 0.6 | M49: 23.666667 | N49: 0 | O49: 3.9 | Q49: =D49/C49 -> 0.13908873

Sheet UPDATEDAppend_48_ANA
A1: Country | B1: # | C1: POS | D1: PLAYER NAME | E1: FIRST NAME(S) | F1: NAME ON SHIRT | G1: DOB | H1: CLUB | I1: HEIGHT (CM) | J1: CAPS | K1: GOALS | L1: LAST NAME(S)
A2: ALG | B2: 1 | C2: GK | D2: MASTIL Melvin | E2: Melvin Feycal | F2: MASTIL | G2: 36575 | H2: FC Stade Nyonnais (SUI) | I2: 194 | J2: 2 | K2: 0
A3: ALG | B3: 2 | C3: DF | D3: MANDI Aissa | E3: Aissa | F3: MANDI | G3: 33533 | H3: Lille OSC (FRA) | I3: 184 | J3: 119 | K3: 8
A4: ALG | B4: 3 | C4: DF | D4: ABADA Achref | E4: Achref | F4: ABADA | G4: 36326 | H4: USM Alger (ALG) | I4: 185 | J4: 9 | K4: 1
A5: ALG | B5: 4 | C5: DF | D5: TOUGAI Mohamed Amine | E5: Mohamed Amine | F5: TOUGAI | G5: 36547 | H5: Espérance De Tunisie (TUN) | I5: 186 | J5: 30 | K5: 2
A6: ALG | B6: 5 | C6: DF | D6: BELAID Zineddine | E6: Zineddine | F6: BELAID | G6: 36239 | H6: JS Kabylie (ALG) | I6: 186 | J6: 18 | K6: 1
A7: ALG | B7: 6 | C7: MF | D7: ZERROUKI Ramiz | E7: Ramiz Larbi | F7: ZERROUKI | G7: 35941 | H7: FC Twente (NED) | I7: 183 | J7: 53 | K7: 3
A8: ALG | B8: 7 | C8: FW | D8: MAHREZ Riyad | E8: Riyad Karim | F8: MAHREZ | G8: 33290 | H8: Al Ahli FC (KSA) | I8: 179 | J8: 116 | K8: 38
A9: ALG | B9: 8 | C9: MF | D9: AOUAR Houssem | E9: Houssem-Eddine Chaabane | F9: AOUAR | G9: 35976 | H9: Al Ittihad (KSA) | I9: 175 | J9: 22 | K9: 6
A10: ALG | B10: 9 | C10: FW | D10: GOUIRI Amine | E10: Amine Ferid | F10: GOUIRI | G10: 36572 | H10: Olympique Marseille (FRA) | I10: 180 | J10: 23 | K10: 10
A11: ALG | B11: 10 | C11: MF | D11: CHAIBI Fares | E11: Fares | F11: CHAIBI | G11: 37588 | H11: Eintracht Frankfurt (GER) | I11: 183 | J11: 31 | K11: 3
A12: ALG | B12: 11 | C12: FW | D12: HADJ MOUSSA Anis | E12: Anis | F12: HADJ MOUSSA | G12: 37298 | H12: Feyenoord Rotterdam (NED) | I12: 176 | J12: 15 | K12: 2
A13: ALG | B13: 12 | C13: FW | D13: BENBOUALI Nadhir | E13: Ahmed Nadhir | F13: BENBOUALI | G13: 36633 | H13: Györi ETO FC (HUN) | I13: 190 | J13: 4 | K13: 1
... A27: ALG | B27: 26 | C27: DF | D27: CHERGUI Samir | E27: Samir Sophian | F27: CHERGUI | G27: 36197 | H27: Paris FC (FRA) | I27: 185 | J27: 5 | K27: 0
A28: AUS | B28: 1 | C28: GK | D28: RYAN Mathew | E28: Mathew David | F28: RYAN | G28: 33702 | H28: Levante UD (ESP) | I28: 184 | J28: 26 | K28: 0 | L28: RYAN
A29: AUS | B29: 2 | C29: DF | D29: DEGENEK Milos | E29: Milos | F29: DEGENEK | G29: 34452 | H29: APOEL FC (CYP) | I29: 187 | J29: 1 | K29: 0 | L29: DEGENEK
A30: AUS | B30: 3 | C30: DF | D30: CIRCATI Alessandro | E30: Alessandro | F30: CIRCATI | G30: 37904 | H30: Parma (ITA) | I30: 191 | J30: 32 | K30: 0 | L30: CIRCATI
A31: AUS | B31: 4 | C31: DF | D31: ITALIANO Jacob | E31: Jacob Michael | F31: ITALIANO | G31: 37102 | H31: Grazer AK (AUT) | I31: 177 | J31: 51 | K31: 4 | L31: ITALIANO
A32: AUS | B32: 5 | C32: DF | D32: BOS Jordan | E32: Jordan Jacob | F32: BOS | G32: 37558 | H32: Feyenoord Rotterdam (NED) | I32: 180 | J32: 52 | K32: 5 | L32: BOS
A33: AUS | B33: 6 | C33: DF | D33: GERIA Jason | E33: Jason Kato | F33: GERIA | G33: 34099 | H33: Albirex Niigata (JPN) | I33: 181 | J33: 47 | K33: 1 | L33: GERIA
A34: AUS | B34: 7 | C34: FW | D34: LECKIE Mathew | E34: Mathew Allan | F34: LECKIE | G34: 33273 | H34: Melbourne City FC (AUS) | I34: 181 | J34: 133 | K34: 47 | L34: LECKIE
A35: AUS | B35: 8 | C35: MF | D35: METCALFE Connor | E35: Connor Isaac | F35: METCALFE | G35: 36469 | H35: FC St. Pauli (GER) | I35: 183 | J35: 113 | K35: 15 | L35: METCALFE
A36: AUS | B36: 9 | C36: FW | D36: TOURE Mohamed | E36: Mohamed A | F36: TOURE | G36: 38072 | H36: Norwich City FC (ENG) | I36: 186 | J36: 98 | K36: 26 | L36: TOURE
A37: AUS | B37: 10 | C37: FW | D37: HRUSTIC Ajdin | E37: Ajdin | F37: HRUSTIC | G37: 35251 | H37: SC Heracles Almelo (NED) | I37: 180 | J37: 58 | K37: 1 | L37: HRUSTIC
A38: AUS | B38: 11 | C38: FW | D38: MABIL Awer | E38: Awer Bul | F38: MABIL | G38: 34957 | H38: CD Castellón (ESP) | I38: 178 | J38: 75 | K38: 24 | L38: MABIL
A39: AUS | B39: 12 | C39: GK | D39: IZZO Paul | E39: Paul David | F39: IZZO | G39: 34705 | H39: Randers FC (DEN) | I39: 184 | J39: 1 | K39: 0 | L39: IZZO
... A1037: RSA | B1037: 22 | C1037: GK | D1037: GOSS Ricardo | E1037: Stuart Ricardo | F1037: GOSS | G1037: 34426 | H1037: Siwelele FC (RSA) | I1037: 181 | J1037: 5 | K1037: 0 | L1037: GOSS
A1038: RSA | B1038: 23 | C1038: MF | D1038: ADAMS Jayden | E1038: Jayden Oswin | F1038: ADAMS | G1038: 37016 | I1038: 177 | J1038: 9 | K1038: 1 | L1038: ADAMS
A1039: RSA | B1039: 24 | C1039: DF | D1039: MAKHANYA Olwethu | E1039: Olwethu Mpilwenhle | F1039: MAKHANYA | G1039: 38107 | H1039: Philadelphia Union (USA) | I1039: 185 | J1039: 1 | K1039: 0 | L1039: MAKHANYA
A1040: RSA | B1040: 25 | C1040: FW | D1040: SEBELEBELE Kamogelo | E1040: Kamogelo Michael | F1040: SEBELEBELE | G1040: 37458 | H1040: Orlando Pirates FC (RSA) | I1040: 166 | J1040: 3 | K1040: 0 | L1040: SEBELEBELE
A1041: RSA | B1041: 26 | C1041: DF | D1041: CROSS Bradley | E1041: Bradley Paul | F1041: CROSS | G1041: 36921 | H1041: Kaizer Chiefs FC (RSA) | I1041: 175 | J1041: 1 | K1041: 0 | L1041: CROSS
A1042: ESP | B1042: 1 | C1042: GK | D1042: RAYA David | E1042: David | F1042: RAYA | G1042: 34957 | H1042: Arsenal FC (ENG) | I1042: 186 | J1042: 13 | K1042: 0 | L1042: RAYA MARTÍN
A1043: ESP | B1043: 2 | C1043: DF | D1043: PUBILL Marc | E1043: Marc | F1043: MARC PUBILL | G1043: 37792 | H1043: Atlético De Madrid (ESP) | I1043: 191 | J1043: 2 | K1043: 0 | L1043: PUBILL PAGES
A1044: ESP | B1044: 3 | C1044: DF | D1044: GRIMALDO Alex | E1044: Alejandro | F1044: GRIMALDO | G1044: 34962 | H1044: Bayer 04 Leverkusen (GER) | I1044: 171 | J1044: 14 | K1044: 0 | L1044: GRIMALDO GARCÍA
A1045: ESP | B1045: 4 | C1045: DF | D1045: GARCIA Eric | E1045: Eric | F1045: ERIC | G1045: 36900 | H1045: FC Barcelona (ESP) | I1045: 183 | J1045: 21 | K1045: 0 | L1045: GARCÍA MARTRET
A1046: ESP | B1046: 5 | C1046: DF | D1046: LLORENTE Marcos | E1046: Marcos | F1046: M. LLORENTE | G1046: 34729 | H1046: Atlético De Madrid (ESP) | I1046: 183 | J1046: 24 | K1046: 0 | L1046: LLORENTE MORENO
A1047: ESP | B1047: 6 | C1047: MF | D1047: MERINO Mikel | E1047: Mikel | F1047: MERINO | G1047: 35238 | H1047: Arsenal FC (ENG) | I1047: 188 | J1047: 43 | K1047: 10 | L1047: MERINO ZAZÓN
A1048: ESP | B1048: 7 | C1048: FW | D1048: TORRES Ferran | E1048: Ferran | F1048: FERRAN | G1048: 36585 | H1048: FC Barcelona (ESP) | I1048: 183 | J1048: 57 | K1048: 24 | L1048: TORRES GARCÍA
A1049: ESP | B1049: 8 | C1049: MF | D1049: RUIZ Fabian | E1049: Fabian | F1049: FABIÁN | G1049: 35158 | H1049: Paris Saint-Germain (FRA) | I1049: 188 | J1049: 42 | K1049: 6 | L1049: RUIZ PEÑA
A1050: ESP | B1050: 9 | C1050: MF | D1050: GAVI | E1050: Pablo | F1050: GAVI | G1050: 38204 | H1050: FC Barcelona (ESP) | I1050: 173 | J1050: 30 | K1050: 5 | L1050: PAEZ GAVIRA
...

Sheet squad_48_teams_2
A1: Country_ANA | B1: Country | C1: # | D1: POS | E1: PLAYER NAME | F1: NAME ON SHIRT | G1: DOB | H1: CLUB | I1: HEIGHT (CM) | J1: CAPS | K1: GOALS
A2: ALG | B2: Algeria | C2: 1 | D2: GK | E2: MASTIL Melvin | F2: MASTIL | G2: 36575 | H2: FC Stade Nyonnais (SUI) | I2: 194 | J2: 2 | K2: 0
A3: ALG | B3: Algeria | C3: 2 | D3: DF | E3: MANDI Aissa | F3: MANDI | G3: 33533 | H3: Lille OSC (FRA) | I3: 184 | J3: 119 | K3: 8
A4: ALG | B4: Algeria | C4: 3 | D4: DF | E4: ABADA Achref | F4: ABADA | G4: 36326 | H4: USM Alger (ALG) | I4: 185 | J4: 9 | K4: 1
A5: ALG | B5: Algeria | C5: 4 | D5: DF | E5: TOUGAI Mohamed Amine | F5: TOUGAI | G5: 36547 | H5: Espérance De Tunisie (TUN) | I5: 186 | J5: 30 | K5: 2
A6: ALG | B6: Algeria | C6: 5 | D6: DF | E6: BELAID Zineddine | F6: BELAID | G6: 36239 | H6: JS Kabylie (ALG) | I6: 186 | J6: 18 | K6: 1
A7: ALG | B7: Algeria | C7: 6 | D7: MF | E7: ZERROUKI Ramiz | F7: ZERROUKI | G7: 35941 | H7: FC Twente (NED) | I7: 183 | J7: 53 | K7: 3
A8: ALG | B8: Algeria | C8: 7 | D8: FW | E8: MAHREZ Riyad | F8: MAHREZ | G8: 33290 | H8: Al Ahli FC (KSA) | I8: 179 | J8: 116 | K8: 38
A9: ALG | B9: Algeria | C9: 8 | D9: MF | E9: AOUAR Houssem | F9: AOUAR | G9: 35976 | H9: Al Ittihad (KSA) | I9: 175 | J9: 22 | K9: 6
A10: ALG | B10: Algeria | C10: 9 | D10: FW | E10: GOUIRI Amine | F10: GOUIRI | G10: 36572 | H10: Olympique Marseille (FRA) | I10: 180 | J10: 23 | K10: 10
A11: ALG | B11: Algeria | C11: 10 | D11: MF | E11: CHAIBI Fares | F11: CHAIBI | G11: 37588 | H11: Eintracht Frankfurt (GER) | I11: 183 | J11: 31 | K11: 3
A12: ALG | B12: Algeria | C12: 11 | D12: FW | E12: HADJ MOUSSA Anis | F12: HADJ MOUSSA | G12: 37298 | H12: Feyenoord Rotterdam (NED) | I12: 176 | J12: 15 | K12: 2
A13: ALG | B13: Algeria | C13: 12 | D13: FW | E13: BENBOUALI Nadhir | F13: BENBOUALI | G13: 36633 | H13: Györi ETO FC (HUN) | I13: 190 | J13: 4 | K13: 1
... A1037: RSA | B1037: South Africa | C1037: 22 | D1037: GK | E1037: GOSS Ricardo | F1037: GOSS | G1037: 34426 | H1037: Siwelele FC (RSA) | I1037: 181 | J1037: 5 | K1037: 0
A1038: RSA | B1038: South Africa | C1038: 23 | D1038: MF | E1038: ADAMS Jayden | F1038: ADAMS | G1038: 37016 | I1038: 177 | J1038: 9 | K1038: 1
A1039: RSA | B1039: South Africa | C1039: 24 | D1039: DF | E1039: MAKHANYA Olwethu | F1039: MAKHANYA | G1039: 38107 | H1039: Philadelphia Union (USA) | I1039: 185 | J1039: 1 | K1039: 0
A1040: RSA | B1040: South Africa | C1040: 25 | D1040: FW | E1040: SEBELEBELE Kamogelo | F1040: SEBELEBELE | G1040: 37458 | H1040: Orlando Pirates FC (RSA) | I1040: 166 | J1040: 3 | K1040: 0
A1041: RSA | B1041: South Africa | C1041: 26 | D1041: DF | E1041: CROSS Bradley | F1041: CROSS | G1041: 36921 | H1041: Kaizer Chiefs FC (RSA) | I1041: 175 | J1041: 1 | K1041: 0
A1042: ESP | B1042: Spain | C1042: 1 | D1042: GK | E1042: RAYA David | F1042: RAYA | G1042: 34957 | H1042: Arsenal FC (ENG) | I1042: 186 | J1042: 13 | K1042: 0
A1043: ESP | B1043: Spain | C1043: 2 | D1043: DF | E1043: PUBILL Marc | F1043: MARC PUBILL | G1043: 37792 | H1043: Atlético De Madrid (ESP) | I1043: 191 | J1043: 2 | K1043: 0
A1044: ESP | B1044: Spain | C1044: 3 | D1044: DF | E1044: GRIMALDO Alex | F1044: GRIMALDO | G1044: 34962 | H1044: Bayer 04 Leverkusen (GER) | I1044: 171 | J1044: 14 | K1044: 0
A1045: ESP | B1045: Spain | C1045: 4 | D1045: DF | E1045: GARCIA Eric | F1045: ERIC | G1045: 36900 | H1045: FC Barcelona (ESP) | I1045: 183 | J1045: 21 | K1045: 0
A1046: ESP | B1046: Spain | C1046: 5 | D1046: DF | E1046: LLORENTE Marcos | F1046: M. LLORENTE | G1046: 34729 | H1046: Atlético De Madrid (ESP) | I1046: 183 | J1046: 24 | K1046: 0
A1047: ESP | B1047: Spain | C1047: 6 | D1047: MF | E1047: MERINO Mikel | F1047: MERINO | G1047: 35238 | H1047: Arsenal FC (ENG) | I1047: 188 | J1047: 43 | K1047: 10
A1048: ESP | B1048: Spain | C1048: 7 | D1048: FW | E1048: TORRES Ferran | F1048: FERRAN | G1048: 36585 | H1048: FC Barcelona (ESP) | I1048: 183 | J1048: 57 | K1048: 24
A1049: ESP | B1049: Spain | C1049: 8 | D1049: MF | E1049: RUIZ Fabian | F1049: FABIÁN | G1049: 35158 | H1049: Paris Saint-Germain (FRA) | I1049: 188 | J1049: 42 | K1049: 6
A1050: ESP | B1050: Spain | C1050: 9 | D1050: MF | E1050: GAVI | F1050: GAVI | G1050: 38204 | H1050: FC Barcelona (ESP) | I1050: 173 | J1050: 30 | K1050: 5
... A1249: UZB | B1249: Uzbekistan | C1249: 26 | D1249: DF | E1249: UROZOV Jakhongir | F1249: UROZOV | G1249: 38004 | H1249: FK Dinamo Samarkand (UZB) | I1249: 190 | J1249: 4 | K1249: 0

Sheet Team Ranking
A1: Last updated: Apr 01, 2026 | E1: https://worldcupstats.football/teams/#sort=delta_points%2Cdesc
B2: Sort | C2: by: | D2: Rank | E2: Points | F2: Trend | G2: Δ | H2: Points | I2: Name
B3: Bosnia | C3: & | D3: Herzegovina | E3: flag
A4: =_xlfn.CONCAT(B3:D3) -> Bosnia&Herzegovina | B4: Rank | C4: #65 | D4: ▲6
B5: Bosnia | C5: & | D5: Herzegovina | E5: 1 | F5: 385.84 | G5: pts | H5: 24 | I5: UEFA | J5: · | K5: B
B6: Sweden | C6: flag
A7: =B6 -> Sweden | B7: Rank | C7: #38 | D7: ▲5
B8: Sweden | C8: 1 | D8: 514.77 | E8: pts | F8: 28 | G8: UEFA | H8: · | I8: F
B9: Turkey | C9: flag
A10: =B9 -> Turkey | B10: Rank | C10: #22 | D10: ▲3
B11: Turkey | C11: 1 | D11: 599.04 | E11: pts | F11: 16 | G11: UEFA | H11: · | I11: D
B12: Ivory | C12: Coast | D12: flag
A13: =_xlfn.CONCAT(B12:C12) -> IvoryCoast | B13: Rank | C13: #34 | D13: ▲3
B14: Ivory | C14: Coast | D14: 1 | E14: 532.98 | F14: pts | G14: 11 | H14: CAF | I14: · | J14: E
B15: Tunisia | C15: flag
A16: =B15 -> Tunisia | B16: Rank | C16: #44 | D16: ▲3
B17: Tunisia | C17: 1 | D17: 483.05 | E17: pts | F17: 4 | G17: CAF | H17: · | I17: F
B18: France | C18: flag
A19: =B18 -> France | B19: Rank | C19: #1 | D19: ▲2
B20: France | C20: 1 | D20: 877.32 | E20: pts | F20: 7 | G20: UEFA | H20: · | I20: I
B21: DR | C21: Congo | D21: flag
A22: =_xlfn.CONCAT(B21:C21) -> DRCongo | B22: Rank | C22: #46 | D22: ▲2
B23: DR | C23: Congo | D23: 1 | E23: 478.35 | F23: pts | G23: 10 | H23: CAF | I23: · | J23: K
B24: Uzbekistan | C24: flag
A25: =B24 -> Uzbekistan | B25: Rank | C25: #50 | D25: ▲2
B26: Uzbekistan | C26: 1 | D26: 465.34 | E26: pts | F26: 3 | G26: AFC | H26: · | I26: K
B27: Portugal | C27: flag
A28: =B27 -> Portugal | B28: Rank | C28: #5 | D28: ▲1
B29: Portugal | C29: 1 | D29: 763.83 | E29: pts | F29: 4 | G29: UEFA | H29: · | I29: K | J29: · | K29: 🪙 | L29: $POR
B30: Colombia | C30: flag
A31: =B30 -> Colombia | B31: Rank | C31: #13 | D31: ▲1
B32: Colombia | C32: 1 | D32: 693.09 | E32: pts | F32: -8 | G32: CONMEBOL | H32: · | I32: K
B33: Mexico | C33: flag
A34: =B33 -> Mexico | B34: Rank | C34: #15 | D34: ▲1
B35: Mexico | C35: 1 | D35: 681.03 | E35: pts | F35: 5 | G35: CONCACAF | H35: · | I35: A
B36: Japan | C36: flag
A37: =B36 -> Japan | B37: Rank | C37: #18 | D37: ▲1
B38: Japan | C38: 1 | D38: 660.43 | E38: pts | F38: 10 | G38: AFC | H38: · | I38: F
B39: Egypt | C39: flag
A40: =B39 -> Egypt | B40: Rank | C40: #29 | D40: ▲1
...

Sheet Coach Salary
A1: Rank | B1: Country | C1: Coach | D1: Annual Salary | H1: https://www.salaryleaks.com/blogs/world-cup-2026-coach-salary-rankings
A2: 1 | B2: Brazil | C2: Carlo Ancelotti | D2: €9.50m
A3: 2 | B3: England | C3: Thomas Tuchel | D3: €5.80m
A4: 3 | B4: United States | C4: Mauricio Pochettino | D4: €5.20m
A5: 4 | B5: Germany | C5: Julian Nagelsmann | D5: €4.80m
A6: 5 | B6: Portugal | C6: Roberto Martinez | D6: €4.00m
A7: 6 | B7: Uzbekistan | C7: Fabio Cannavaro | D7: €4.00m
A8: 7 | B8: France | C8: Didier Deschamps | D8: €3.80m
A9: 8 | B9: Argentina | C9: Lionel Scaloni | D9: €3.00m
A10: 9 | B10: Netherlands | C10: Ronald Koeman | D10: €3.00m
A11: 10 | B11: Uruguay | C11: Marcelo Bielsa | D11: €3.00m
A12: 11 | B12: Canada | C12: Jesse Marsch | D12: €2.50m
A13: 12 | B13: Mexico | C13: Javier Aguirre | D13: €2.50m
... A49: 48 | B49: Curaçao | C49: Dick Advocaat | D49: €96k

Sheet 208Team_match_stat
A1: Date | B1: Team | C1: Team_ANA | D1: (X1) International player contract transfers (incoming+ outgoing) 2025 | E1: (X2) Coach Salary (EURO) | F1: (X3) Ranking (April 2026) | G1: (X4) FW Goal rate | H1: (X5) Squad Goals | I1: (X6) FW Goal Avg | J1: (X7) FW Mean cap | K1: (X8) MF Mean cap | L1: Xgoals | M1: ( Y ) Goals Scored
A2: 46184 | B2: Mexico | C2: MEX | D2: 178 | E2: 2500000 | F2: 15 | G2: 0.20626632 | H2: 127 | I2: =_xlfn.XLOOKUP(C2,#REF!,#REF!) -> #REF! | J2: =_xlfn.XLOOKUP(C2,#REF!,#REF!) -> #REF! | K2: =_xlfn.XLOOKUP(C2,#REF!,#REF!) -> #REF! | L2: =_xlfn.XLOOKUP('208Team_match_stat'!C2,#REF!,#REF!) -> #REF! | M2: 2
A3: 46185 | B3: South Korea | C3: KOR | D3: 103 | E3: 2160000 | F3: 25 | G3: 0.33632287 | H3: 144 | I3: =_xlfn.XLOOKUP(C3,#REF!,#REF!) -> #REF! | J3: =_xlfn.XLOOKUP(C3,#REF!,#REF!) -> #REF! | K3: =_xlfn.XLOOKUP(C3,#REF!,#REF!) -> #REF! | L3: =_xlfn.XLOOKUP('208Team_match_stat'!C3,#REF!,#REF!) -> #REF! | M3: 2
A4: 46185 | B4: Canada | C4: CAN | D4: 90 | E4: 2500000 | F4: 30 | G4: 0.2804878 | H4: 141 | I4: =_xlfn.XLOOKUP(C4,#REF!,#REF!) -> #REF! | J4: =_xlfn.XLOOKUP(C4,#REF!,#REF!) -> #REF! | K4: =_xlfn.XLOOKUP(C4,#REF!,#REF!) -> #REF! | L4: =_xlfn.XLOOKUP('208Team_match_stat'!C4,#REF!,#REF!) -> #REF! | M4: 1
A5: 46186 | B5: USA | C5: USA | D5: 287 | E5: 5200000 | F5: 16 | G5: 0.26602564 | H5: 134 | I5: =_xlfn.XLOOKUP(C5,#REF!,#REF!) -> #REF! | J5: =_xlfn.XLOOKUP(C5,#REF!,#REF!) -> #REF! | K5: =_xlfn.XLOOKUP(C5,#REF!,#REF!) -> #REF! | L5: =_xlfn.XLOOKUP('208Team_match_stat'!C5,#REF!,#REF!) -> #REF! | M5: 4
A6: 46186 | B6: Qatar | C6: QAT | D6: 31 | E6: 2400000 | F6: 55 | G6: 0.24137931 | H6: 217 | I6: =_xlfn.XLOOKUP(C6,#REF!,#REF!) -> #REF! | J6: =_xlfn.XLOOKUP(C6,#REF!,#REF!) -> #REF! | K6: =_xlfn.XLOOKUP(C6,#REF!,#REF!) -> #REF! | L6: =_xlfn.XLOOKUP('208Team_match_stat'!C6,#REF!,#REF!) -> #REF! | M6: 1
A7: 46186 | B7: Brazil | C7: BRA | D7: 660 | E7: 9500000 | F7: 6 | G7: 0.37195122 | H7: 162 | I7: =_xlfn.XLOOKUP(C7,#REF!,#REF!) -> #REF! | J7: =_xlfn.XLOOKUP(C7,#REF!,#REF!) -> #REF! | K7: =_xlfn.XLOOKUP(C7,#REF!,#REF!) -> #REF! | L7: =_xlfn.XLOOKUP('208Team_match_stat'!C7,#REF!,#REF!) -> #REF! | M7: 1
A8: 46187 | B8: Haiti | C8: HAI | D8: 2 | E8: 190000 | F8: 83 | G8: 0.3800738 | H8: 116 | I8: =_xlfn.XLOOKUP(C8,#REF!,#REF!) -> #REF! | J8: =_xlfn.XLOOKUP(C8,#REF!,#REF!) -> #REF! | K8: =_xlfn.XLOOKUP(C8,#REF!,#REF!) -> #REF! | L8: =_xlfn.XLOOKUP('208Team_match_stat'!C8,#REF!,#REF!) -> #REF! | M8: 0
A9: 46187 | B9: Australia | C9: AUS | D9: 111 | E9: 605000 | F9: 27 | G9: 0.1875 | H9: 75 | I9: =_xlfn.XLOOKUP(C9,#REF!,#REF!) -> #REF! | J9: =_xlfn.XLOOKUP(C9,#REF!,#REF!) -> #REF! | K9: =_xlfn.XLOOKUP(C9,#REF!,#REF!) -> #REF! | L9: =_xlfn.XLOOKUP('208Team_match_stat'!C9,#REF!,#REF!) -> #REF! | M9: 2
A10: 46187 | B10: Germany | C10: GER | D10: 262 | E10: 4800000 | F10: 10 | G10: 0.39175258 | H10: 116 | I10: =_xlfn.XLOOKUP(C10,#REF!,#REF!) -> #REF! | J10: =_xlfn.XLOOKUP(C10,#REF!,#REF!) -> #REF! | K10: =_xlfn.XLOOKUP(C10,#REF!,#REF!) -> #REF! | L10: =_xlfn.XLOOKUP('208Team_match_stat'!C10,#REF!,#REF!) -> #REF! | M10: 7
A11: 46187 | B11: Netherlands | C11: NED | D11: 148 | E11: 3000000 | F11: 7 | G11: 0.36624204 | H11: 163 | I11: =_xlfn.XLOOKUP(C11,#REF!,#REF!) -> #REF! | J11: =_xlfn.XLOOKUP(C11,#REF!,#REF!) -> #REF! | K11: =_xlfn.XLOOKUP(C11,#REF!,#REF!) -> #REF! | L11: =_xlfn.XLOOKUP('208Team_match_stat'!C11,#REF!,#REF!) -> #REF! | M11: 2
A12: 46188 | B12: Saudi Arabia | C12: RSA | D12: 146 | E12: 1040000 | F12: 61 | G12: 0.20238095 | H12: 68 | I12: =_xlfn.XLOOKUP(C12,#REF!,#REF!) -> #REF! | J12: =_xlfn.XLOOKUP(C12,#REF!,#REF!) -> #REF! | K12: =_xlfn.XLOOKUP(C12,#REF!,#REF!) -> #REF! | L12: =_xlfn.XLOOKUP('208Team_match_stat'!C12,#REF!,#REF!) -> #REF! | M12: 1
A13: 46188 | B13: Belgium | C13: BEL | D13: 153 | E13: 1700000 | F13: 9 | G13: 0.41612903 | H13: 227 | I13: =_xlfn.XLOOKUP(C13,#REF!,#REF!) -> #REF! | J13: =_xlfn.XLOOKUP(C13,#REF!,#REF!) -> #REF! | K13: =_xlfn.XLOOKUP(C13,#REF!,#REF!) -> #REF! | L13: =_xlfn.XLOOKUP('208Team_match_stat'!C13,#REF!,#REF!) -> #REF! | M13: 1
... A105: 46222 | B105: Spain | C105: ESP | D105: 421 | E105: 2000000 | F105: 2 | G105: 0.29411765 | H105: 130 | I105: =_xlfn.XLOOKUP(C105,#REF!,#REF!) -> #REF! | J105: =_xlfn.XLOOKUP(C105,#REF!,#REF!) -> #REF! | K105: =_xlfn.XLOOKUP(C105,#REF!,#REF!) -> #REF! | L105: =_xlfn.XLOOKUP('208Team_match_stat'!C105,#REF!,#REF!) -> #REF! | M105: 1
A106: 46184 | B106: South Africa | C106: RSA | D106: 49 | E106: 900000 | F106: 60 | G106: 0.20238095 | H106: 68 | I106: =_xlfn.XLOOKUP(C106,#REF!,#REF!) -> #REF! | J106: =_xlfn.XLOOKUP(C106,#REF!,#REF!) -> #REF! | K106: =_xlfn.XLOOKUP(C106,#REF!,#REF!) -> #REF! | L106: =_xlfn.XLOOKUP(C106,#REF!,#REF!) -> #REF! | M106: 0
A107: 46185 | B107: Czech Republic | C107: CZE | D107: 100 | E107: 180000 | F107: 41 | G107: 0.25603865 | H107: 100 | I107: =_xlfn.XLOOKUP(C107,#REF!,#REF!) -> #REF! | J107: =_xlfn.XLOOKUP(C107,#REF!,#REF!) -> #REF! | K107: =_xlfn.XLOOKUP(C107,#REF!,#REF!) -> #REF! | L107: =_xlfn.XLOOKUP(C107,#REF!,#REF!) -> #REF! | M107: 1
A108: 46185 | B108: Bosnia & Herzegovina | C108: BIH | D108: 88 | E108: 230000 | F108: 65 | G108: 0.33204633 | H108: 97 | I108: =_xlfn.XLOOKUP(C108,#REF!,#REF!) -> #REF! | J108: =_xlfn.XLOOKUP(C108,#REF!,#REF!) -> #REF! | K108: =_xlfn.XLOOKUP(C108,#REF!,#REF!) -> #REF! | L108: =_xlfn.XLOOKUP(C108,#REF!,#REF!) -> #REF! | M108: 1
A109: 46186 | B109: Paraguay | C109: PAR | D109: 118 | E109: 2500000 | F109: 40 | G109: 0.12209302 | H109: 56 | I109: =_xlfn.XLOOKUP(C109,#REF!,#REF!) -> #REF! | J109: =_xlfn.XLOOKUP(C109,#REF!,#REF!) -> #REF! | K109: =_xlfn.XLOOKUP(C109,#REF!,#REF!) -> #REF! | L109: =_xlfn.XLOOKUP(C109,#REF!,#REF!) -> #REF! | M109: 1
A110: 46186 | B110: Switzerland | C110: SUI | D110: 84 | E110: 1600000 | F110: 19 | G110: 0.24242424 | H110: 134 | I110: =_xlfn.XLOOKUP(C110,#REF!,#REF!) -> #REF! | J110: =_xlfn.XLOOKUP(C110,#REF!,#REF!) -> #REF! | K110: =_xlfn.XLOOKUP(C110,#REF!,#REF!) -> #REF! | L110: =_xlfn.XLOOKUP(C110,#REF!,#REF!) -> #REF! | M110: 1
A111: 46186 | B111: Morocco | C111: MAR | D111: 127 | E111: 775000 | F111: 8 | G111: 0.40909091 | H111: 109 | I111: =_xlfn.XLOOKUP(C111,#REF!,#REF!) -> #REF! | J111: =_xlfn.XLOOKUP(C111,#REF!,#REF!) -> #REF! | K111: =_xlfn.XLOOKUP(C111,#REF!,#REF!) -> #REF! | L111: =_xlfn.XLOOKUP(C111,#REF!,#REF!) -> #REF! | M111: 1
A112: 46187 | B112: Scotland | C112: SCO | D112: 139 | E112: 500000 | F112: 43 | G112: 0.20496894 | H112: 99 | I112: =_xlfn.XLOOKUP(C112,#REF!,#REF!) -> #REF! | J112: =_xlfn.XLOOKUP(C112,#REF!,#REF!) -> #REF! | K112: =_xlfn.XLOOKUP(C112,#REF!,#REF!) -> #REF! | L112: =_xlfn.XLOOKUP(C112,#REF!,#REF!) -> #REF! | M112: 1
A113: 46187 | B113: Turkey | C113: TUR | D113: 146 | E113: 2200000 | F113: 22 | G113: 0.17647059 | H113: 100 | I113: =_xlfn.XLOOKUP(C113,#REF!,#REF!) -> #REF! | J113: =_xlfn.XLOOKUP(C113,#REF!,#REF!) -> #REF! | K113: =_xlfn.XLOOKUP(C113,#REF!,#REF!) -> #REF! | L113: =_xlfn.XLOOKUP(C113,#REF!,#REF!) -> #REF! | M113: 0
A114: 46187 | B114: Curacao | C114: CUW | D114: 0 | E114: 96000 | F114: 82 | G114: 0.15104167 | H114: 73 | I114: =_xlfn.XLOOKUP(C114,#REF!,#REF!) -> #REF! | J114: =_xlfn.XLOOKUP(C114,#REF!,#REF!) -> #REF! | K114: =_xlfn.XLOOKUP(C114,#REF!,#REF!) -> #REF! | L114: =_xlfn.XLOOKUP(C114,#REF!,#REF!) -> #REF! | M114: 1
A115: 46187 | B115: Japan | C115: JPN | D115: 126 | E115: 865000 | F115: 18 | G115: 0.4 | H115: 121 | I115: =_xlfn.XLOOKUP(C115,#REF!,#REF!) -> #REF! | J115: =_xlfn.XLOOKUP(C115,#REF!,#REF!) -> #REF! | K115: =_xlfn.XLOOKUP(C115,#REF!,#REF!) -> #REF! | L115: =_xlfn.XLOOKUP(C115,#REF!,#REF!) -> #REF! | M115: 2
A116: 46188 | B116: Uruguay | C116: URU | D116: 203 | E116: 3000000 | F116: 17 | G116: 0.17021277 | H116: 77 | I116: =_xlfn.XLOOKUP(C116,#REF!,#REF!) -> #REF! | J116: =_xlfn.XLOOKUP(C116,#REF!,#REF!) -> #REF! | K116: =_xlfn.XLOOKUP(C116,#REF!,#REF!) -> #REF! | L116: =_xlfn.XLOOKUP(C116,#REF!,#REF!) -> #REF! | M116: 1
A117: 46188 | B117: Egypt | C117: EGY | D117: 121 | E117: 156000 | F117: 29 | G117: 0.29133858 | H117: 136 | I117: =_xlfn.XLOOKUP(C117,#REF!,#REF!) -> #REF! | J117: =_xlfn.XLOOKUP(C117,#REF!,#REF!) -> #REF! | K117: =_xlfn.XLOOKUP(C117,#REF!,#REF!) -> #REF! | L117: =_xlfn.XLOOKUP(C117,#REF!,#REF!) -> #REF! | M117: 1
... A209: 46222 | B209: Argentina | C209: ARG | D209: 465 | E209: 3000000 | F209: 3 | G209: 0.46419753 | H209: 241 | I209: =_xlfn.XLOOKUP(C209,#REF!,#REF!) -> #REF! | J209: =_xlfn.XLOOKUP(C209,#REF!,#REF!) -> #REF! | K209: =_xlfn.XLOOKUP(C209,#REF!,#REF!) -> #REF! | L209: =_xlfn.XLOOKUP(C209,#REF!,#REF!) -> #REF! | M209: 0

Sheet Transfer report25
A1: Fifa Global Transfer Report 2025 | J1: CHOOSE TRANSFER REPORTS 23-25 AS THERE WAS A REFORM OF THE SYSTEM IN 2023
A2: Member association | B2: Confederation | C2: Incoming transfers | D2: Outgoing transfers | E2: Transfer fees spent (USD) | F2: Transfer fees received (USD) | G2: Growth rate incoming transfers | H2: Growth rate outgoing transfers | J2: CHOOSE TO LOOK AT TRANSFER REPORTS AS AN INDICATOR OF GOAL DIFFERENCE PREDICTOR- AGGRESSIVE SPENDING ON INTERNATIONAL PLAYER TRANSFER MAY INDICATE AMORE AGGRESSIVESTYLE OF PLAYOR THAT MONEY WAS SPENT ON TOP GOAL SCORERS
A3: Afghanistan | B3: AFC | C3: 0 | D3: 1 | E3: 0 | F3: 0 | G3: 0 | H3: 0 | J3: CHOOSE CUMULATIVE SPENDING SINCE LAST WORK CUP
A4: Albania | B4: UEFA | C4: 78 | D4: 26 | E4: 0 | F4: 382810 | G4: 0.472 | H4: -0.381 | J4: https://inside.fifa.co | K4: /transfer-syste | L4: /transfer-reports
A5: Algeria | B5: CAF | C5: 23 | D5: 28 | E5: 1785236 | F5: 0 | G5: 0.533 | H5: 0.474
A6: American Samoa | B6: OFC | C6: 0 | D6: 0 | E6: 0 | F6: 0 | G6: 0 | H6: 0
A7: Andorra | B7: UEFA | C7: 25 | D7: 16 | E7: 0 | F7: 0 | G7: -0.405 | H7: 0
A8: Angola | B8: CAF | C8: 13 | D8: 13 | E8: 81388 | F8: 0 | G8: 0.444 | H8: 1.6
A9: Anguilla | B9: Concacaf | C9: 0 | D9: 1 | E9: 0 | F9: 0 | G9: 0 | H9: 0
A10: Antigua and Barbuda | B10: Concacaf | C10: 1 | D10: 1 | E10: 0 | F10: 0 | G10: 0 | H10: 0
A11: Argentina | B11: CONMEBOL | C11: 237 | D11: 228 | E11: 19903775 | F11: 30926229 | G11: -0.092 | H11: -0.106
A12: Armenia | B12: UEFA | C12: 3 | D12: 17 | E12: 0 | F12: 0 | G12: -0.667 | H12: 0
A13: Aruba | B13: Concacaf | C13: 0 | D13: 0 | E13: 0 | F13: 0 | G13: 0 | H13: 0
A14: Australia | B14: AFC | C14: 77 | D14: 34 | E14: 0 | F14: 1974378 | G14: -0.313 | H14: 0.478
A15: Austria | B15: UEFA | C15: 25 | D15: 48 | E15: 4713301 | F15: 37781985 | G15: -0.432 | H15: 0
A16: Azerbaijan | B16: UEFA | C16: 16 | D16: 11 | E16: 1225359 | F16: 468792 | G16: -0.36 | H16: -0.083
... A89: Honduras | B89: Concacaf | C89: 53 | D89: 24 | E89: 0 | F89: 0 | G89: -0.338 | H89: 0.263
A90: Hong Kong
A91: Hungary | B91: UEFA | C91: 37 | D91: 21 | E91: 7576240 | F91: 23837960 | G91: 0 | H91: -0.192
A92: Iceland | B92: UEFA | C92: 0 | D92: 19 | E92: 0 | F92: 629396 | G92: -1 | H92: 0.583
A93: India | B93: AFC | C93: 21 | D93: 48 | E93: 0 | F93: 0 | G93: 0.05 | H93: 1.182
A94: Indonesia | B94: AFC | C94: 64 | D94: 29 | E94: 184335 | F94: 0 | G94: 0.882 | H94: 0.036
A95: IR Iran | B95: AFC | C95: 8 | D95: 7 | E95: 669227 | F95: 0 | G95: -0.333 | H95: -0.5
A96: Iraq | B96: AFC | C96: 74 | D96: 42 | E96: 61500 | F96: 1400000 | G96: 0.345 | H96: 0.4
A97: Israel | B97: UEFA | C97: 33 | D97: 20 | E97: 870777 | F97: 8921361 | G97: 0.065 | H97: -0.167
A98: Italy | B98: UEFA | C98: 128 | D98: 149 | E98: 282460136 | F98: 174789144 | G98: -0.008 | H98: 0.146
A99: Jamaica | B99: Concacaf | C99: 11 | D99: 5 | E99: 0 | F99: 0 | G99: -0.5 | H99: 0
A100: Japan | B100: AFC | C100: 36 | D100: 90 | E100: 3544292 | F100: 11986382 | G100: -0.493 | H100: 0.233
A101: Jordan | B101: AFC | C101: 26 | D101: 16 | E101: 0 | F101: 622500 | G101: 0.368 | H101: -0.111
A102: Kazakhstan | B102: UEFA | C102: 12 | D102: 19 | E102: 0 | F102: 0 | G102: 0.5 | H102: -0.525
... A213: Zimbabwe | B213: CAF | C213: 3 | D213: 10 | E213: 0 | F213: 0 | G213: -0.4 | H213: 0.111

Sheet CountryANA
A1: Teams | B1: Country ANA
A2: Mexico | B2: MEX
A3: South Korea | B3: KOR
A4: Canada | B4: CAN
A5: USA | B5: USA
A6: Qatar | B6: QAT
A7: Brazil | B7: BRA
A8: Haiti | B8: HAI
A9: Australia | B9: AUS
A10: Germany | B10: GER
A11: Netherlands | B11: NED
A12: Saudi Arabia | B12: RSA
... A49: Algeria | B49: ALG

Sheet Round number
A1: Round category | B1: Round Number | C1: Date | D1: Home Team | E1: Away Team | F1: T1_ANA | G1: T2_ANA
A2: 1 | B2: 1 | C2: 46184.792 | D2: Mexico | E2: South Africa | F2: MEX | G2: RSA
A3: 1 | B3: 1 | C3: 46185.083 | D3: Korea Republic | E3: Czechia | F3: KOR | G3: CZE
A4: 1 | B4: 1 | C4: 46185.792 | D4: Canada | E4: Bosnia and Herzegovina | F4: CAN | G4: BIH
A5: 1 | B5: 1 | C5: 46186.042 | D5: USA | E5: Paraguay | F5: USA | G5: PAR
A6: 1 | B6: 1 | C6: 46186.792 | D6: Qatar | E6: Switzerland | F6: QAT | G6: SUI
A7: 1 | B7: 1 | C7: 46186.917 | D7: Brazil | E7: Morocco | F7: BRA | G7: MAR
A8: 1 | B8: 1 | C8: 46187.042 | D8: Haiti | E8: Scotland | F8: HAI | G8: SCO
A9: 1 | B9: 1 | C9: 46187.167 | D9: Australia | E9: Türkiye | F9: AUS | G9: TUR
A10: 1 | B10: 1 | C10: 46187.708 | D10: Germany | E10: Curaçao | F10: GER | G10: CUW
A11: 1 | B11: 1 | C11: 46187.833 | D11: Netherlands | E11: Japan | F11: NED | G11: JPN
A12: 1 | B12: 1 | C12: 46187.958 | D12: Côte d'Ivoire | E12: Ecuador | F12: CIV | G12: ECU
A13: 1 | B13: 1 | C13: 46188.083 | D13: Sweden | E13: Tunisia | F13: SWE | G13: TUN
... A73: 3 | B73: 3 | C73: 46201.083 | D73: Jordan | E73: Argentina | F73: JOR | G73: ARG
A74: 4 | B74: Round of 32 | C74: 46201.792 | D74: South Africa | E74: Canada | F74: RSA | G74: CAN
A75: 4 | B75: Round of 32 | C75: 46202.708 | D75: Brazil | E75: Japan | F75: BRA | G75: JPN
A76: 4 | B76: Round of 32 | C76: 46202.854 | D76: Germany | E76: Paraguay | F76: GER | G76: PAR
A77: 4 | B77: Round of 32 | C77: 46203.042 | D77: Netherlands | E77: Morocco | F77: NED | G77: MAR
A78: 4 | B78: Round of 32 | C78: 46203.708 | D78: Côte d'Ivoire | E78: Norway | F78: CIV | G78: NOR
A79: 4 | B79: Round of 32 | C79: 46203.875 | D79: France | E79: Sweden | F79: FRA | G79: SWE
A80: 4 | B80: Round of 32 | C80: 46204.083 | D80: Mexico | E80: Ecuador | F80: MEX | G80: ECU
A81: 4 | B81: Round of 32 | C81: 46204.667 | D81: England | E81: Congo DR | F81: ENG | G81: COD
A82: 4 | B82: Round of 32 | C82: 46204.833 | D82: Belgium | E82: Senegal | F82: BEL | G82: SEN
A83: 4 | B83: Round of 32 | C83: 46205 | D83: USA | E83: Bosnia and Herzegovina | F83: USA | G83: BIH
A84: 4 | B84: Round of 32 | C84: 46205.792 | D84: Spain | E84: Austria | F84: ESP | G84: AUT
A85: 4 | B85: Round of 32 | C85: 46205.958 | D85: Portugal | E85: Croatia | F85: POR | G85: CRO
... A105: 8 | B105: Finals | C105: 46222.792 | D105: Spain | E105: Argentina | F105: ESP | G105: ARG

Sheet Fifa_team_variables_ro
A1: Teams | B1: International player contract transfers (incoming+ outgoing) 2025 | C1: Coach Salary (EURO) | D1: Ranking (April 2026) | E1: International Player Transfer fees spent (USD) (Fifa Global Transfer Report 2025)
A2: Mexico | B2: 178 | C2: 2500000 | D2: 15 | E2: 37380617
A3: South Korea | B3: 103 | C3: 2160000 | D3: 25 | E3: 3823924
A4: Canada | B4: 90 | C4: 2500000 | D4: 30 | E4: 1595000
A5: USA | B5: 287 | C5: 5200000 | D5: 16 | E5: 99305021
A6: Qatar | B6: 31 | C6: 2400000 | D6: 55 | E6: 3311110
A7: Brazil | B7: 660 | C7: 9500000 | D7: 6 | E7: 179848120
A8: Haiti | B8: 2 | C8: 190000 | D8: 83 | E8: 0
A9: Australia | B9: 111 | C9: 605000 | D9: 27 | E9: 0
A10: Germany | B10: 262 | C10: 4800000 | D10: 10 | E10: 125798255
A11: Netherlands | B11: 148 | C11: 3000000 | D11: 7 | E11: 21764968
A12: Saudi Arabia | B12: 146 | C12: 1040000 | D12: 61 | E12: 101089441
A13: Belgium | B13: 153 | C13: 1700000 | D13: 9 | E13: 44391148
... A49: Algeria | B49: 51 | C49: 1380000 | D49: 28 | E49: 1785236
